<?xml version="1.0" ?>
<robot name="LeggedRobot" xmlns:xacro="http://www.ros.org/wiki/xacro">

<xacro:include filename="$(find LeggedRobot_description)/urdf/materials.xacro" />
<xacro:include filename="$(find LeggedRobot_description)/urdf/LeggedRobot.trans" />
<xacro:include filename="$(find LeggedRobot_description)/urdf/LeggedRobot.gazebo" />
<link name="base_link">
  <inertial>
    <origin xyz="-6.346783925452715e-17 -5.077427140362172e-17 0.12027129926675365" rpy="0 0 0"/>
    <mass value="5.237474955117158"/>
    <inertia ixx="0.018691" iyy="0.017694" izz="0.016812" ixy="-0.0" iyz="-0.0" ixz="-0.0"/>
  </inertial>
  <visual>
    <origin xyz="0 0 0" rpy="0 0 0"/>
    <geometry>
      <mesh filename="../meshes/base_link.stl"/>
    </geometry>
    <material name="silver"/>
  </visual>
  <collision>
    <origin xyz="0 0 0" rpy="0 0 0"/>
    <geometry>
      <mesh filename="../meshes/base_link.stl"/>
    </geometry>
  </collision>
</link>

<link name="Upper_leg_v2__1__1">
  <inertial>
    <origin xyz="2.6254089049651695e-16 0.02000000000000001 -0.07192876729347267" rpy="0 0 0"/>
    <mass value="0.1431308285816426"/>
    <inertia ixx="0.000346" iyy="0.000326" izz="5.6e-05" ixy="0.0" iyz="0.0" ixz="0.0"/>
  </inertial>
  <visual>
    <origin xyz="-0.0 -0.03 0.000399" rpy="0 0 0"/>
    <geometry>
      <mesh filename="../meshes/Upper_leg_v2__1__1.stl"/>
    </geometry>
    <material name="silver"/>
  </visual>
  <collision>
    <origin xyz="-0.0 -0.03 0.000399" rpy="0 0 0"/>
    <geometry>
      <mesh filename="../meshes/Upper_leg_v2__1__1.stl"/>
    </geometry>
  </collision>
</link>

<link name="Lower_leg_v2__1__1">
  <inertial>
    <origin xyz="0.0036759081332830533 0.015000001797078708 -0.058757577943002876" rpy="0 0 0"/>
    <mass value="0.301868005898131"/>
    <inertia ixx="0.000629" iyy="0.000642" izz="6.2e-05" ixy="0.0" iyz="0.0" ixz="2.2e-05"/>
  </inertial>
  <visual>
    <origin xyz="-0.0 -0.035 0.140399" rpy="0 0 0"/>
    <geometry>
      <mesh filename="../meshes/Lower_leg_v2__1__1.stl"/>
    </geometry>
    <material name="silver"/>
  </visual>
  <collision>
    <origin xyz="-0.0 -0.035 0.140399" rpy="0 0 0"/>
    <geometry>
      <mesh filename="../meshes/Lower_leg_v2__1__1.stl"/>
    </geometry>
  </collision>
</link>

<link name="Lower_leg_v2_1">
  <inertial>
    <origin xyz="0.003675908133282827 0.015000001797078687 -0.05875791626802551" rpy="0 0 0"/>
    <mass value="0.301868005898131"/>
    <inertia ixx="0.000629" iyy="0.000642" izz="6.2e-05" ixy="0.0" iyz="0.0" ixz="2.2e-05"/>
  </inertial>
  <visual>
    <origin xyz="-0.0 0.065 0.140258" rpy="0 0 0"/>
    <geometry>
      <mesh filename="../meshes/Lower_leg_v2_1.stl"/>
    </geometry>
    <material name="silver"/>
  </visual>
  <collision>
    <origin xyz="-0.0 0.065 0.140258" rpy="0 0 0"/>
    <geometry>
      <mesh filename="../meshes/Lower_leg_v2_1.stl"/>
    </geometry>
  </collision>
</link>

<link name="Ankle_v1__1__1">
  <inertial>
    <origin xyz="0.001958378003147534 0.014999777263784618 5.238469396035006e-05" rpy="0 0 0"/>
    <mass value="0.013454867594222361"/>
    <inertia ixx="0.0" iyy="5e-06" izz="5e-06" ixy="-0.0" iyz="-0.0" ixz="-0.0"/>
  </inertial>
  <visual>
    <origin xyz="-0.0 0.065 0.280258" rpy="0 0 0"/>
    <geometry>
      <mesh filename="../meshes/Ankle_v1__1__1.stl"/>
    </geometry>
    <material name="silver"/>
  </visual>
  <collision>
    <origin xyz="-0.0 0.065 0.280258" rpy="0 0 0"/>
    <geometry>
      <mesh filename="../meshes/Ankle_v1__1__1.stl"/>
    </geometry>
  </collision>
</link>

<link name="Ankle_v1__2__1">
  <inertial>
    <origin xyz="0.001958378003147778 0.01499977726378466 5.27230189829031e-05" rpy="0 0 0"/>
    <mass value="0.013454867594222361"/>
    <inertia ixx="0.0" iyy="5e-06" izz="5e-06" ixy="-0.0" iyz="-0.0" ixz="-0.0"/>
  </inertial>
  <visual>
    <origin xyz="-0.0 -0.035 0.280399" rpy="0 0 0"/>
    <geometry>
      <mesh filename="../meshes/Ankle_v1__2__1.stl"/>
    </geometry>
    <material name="silver"/>
  </visual>
  <collision>
    <origin xyz="-0.0 -0.035 0.280399" rpy="0 0 0"/>
    <geometry>
      <mesh filename="../meshes/Ankle_v1__2__1.stl"/>
    </geometry>
  </collision>
</link>

<link name="Foot_v1__1__1">
  <inertial>
    <origin xyz="0.05260285295726415 1.0137375216351385e-07 -0.03676333019729189" rpy="0 0 0"/>
    <mass value="0.18191482193416827"/>
    <inertia ixx="9.7e-05" iyy="0.000254" izz="0.000307" ixy="0.0" iyz="-0.0" ixz="1e-05"/>
  </inertial>
  <visual>
    <origin xyz="0.035 -0.05 0.280328" rpy="0 0 0"/>
    <geometry>
      <mesh filename="../meshes/Foot_v1__1__1.stl"/>
    </geometry>
    <material name="silver"/>
  </visual>
  <collision>
    <origin xyz="0.035 -0.05 0.280328" rpy="0 0 0"/>
    <geometry>
      <mesh filename="../meshes/Foot_v1__1__1.stl"/>
    </geometry>
  </collision>
</link>

<link name="Foot_v1_1">
  <inertial>
    <origin xyz="0.052602852957263996 1.0137375208024713e-07 -0.03676266852231441" rpy="0 0 0"/>
    <mass value="0.18191482193416827"/>
    <inertia ixx="9.7e-05" iyy="0.000254" izz="0.000307" ixy="0.0" iyz="-0.0" ixz="1e-05"/>
  </inertial>
  <visual>
    <origin xyz="0.035 0.05 0.280188" rpy="0 0 0"/>
    <geometry>
      <mesh filename="../meshes/Foot_v1_1.stl"/>
    </geometry>
    <material name="silver"/>
  </visual>
  <collision>
    <origin xyz="0.035 0.05 0.280188" rpy="0 0 0"/>
    <geometry>
      <mesh filename="../meshes/Foot_v1_1.stl"/>
    </geometry>
  </collision>
</link>

<link name="Hip_joint_v1__1__1">
  <inertial>
    <origin xyz="-0.03822219731670742 2.0634426864396538e-07 2.243850123965943e-05" rpy="0 0 0"/>
    <mass value="0.015566398617684687"/>
    <inertia ixx="1e-06" iyy="5e-06" izz="6e-06" ixy="0.0" iyz="-0.0" ixz="0.0"/>
  </inertial>
  <visual>
    <origin xyz="-0.04 0.05 0.000328" rpy="0 0 0"/>
    <geometry>
      <mesh filename="../meshes/Hip_joint_v1__1__1.stl"/>
    </geometry>
    <material name="silver"/>
  </visual>
  <collision>
    <origin xyz="-0.04 0.05 0.000328" rpy="0 0 0"/>
    <geometry>
      <mesh filename="../meshes/Hip_joint_v1__1__1.stl"/>
    </geometry>
  </collision>
</link>

<link name="Upper_leg_v2_1">
  <inertial>
    <origin xyz="3.523342660544597e-17 0.019999999999999962 -0.07192910561849525" rpy="0 0 0"/>
    <mass value="0.1431308285816426"/>
    <inertia ixx="0.000346" iyy="0.000326" izz="5.6e-05" ixy="-0.0" iyz="0.0" ixz="0.0"/>
  </inertial>
  <visual>
    <origin xyz="-0.0 0.07 0.000258" rpy="0 0 0"/>
    <geometry>
      <mesh filename="../meshes/Upper_leg_v2_1.stl"/>
    </geometry>
    <material name="silver"/>
  </visual>
  <collision>
    <origin xyz="-0.0 0.07 0.000258" rpy="0 0 0"/>
    <geometry>
      <mesh filename="../meshes/Upper_leg_v2_1.stl"/>
    </geometry>
  </collision>
</link>

<link name="Hip_v1_1">
  <inertial>
    <origin xyz="0.002298444106988769 -8.467524528557591e-07 -0.013356564577291896" rpy="0 0 0"/>
    <mass value="0.07120981938348954"/>
    <inertia ixx="2.6e-05" iyy="7e-05" izz="5.4e-05" ixy="0.0" iyz="0.0" ixz="0.0"/>
  </inertial>
  <visual>
    <origin xyz="0.0 0.05 -0.045" rpy="0 0 0"/>
    <geometry>
      <mesh filename="../meshes/Hip_v1_1.stl"/>
    </geometry>
    <material name="silver"/>
  </visual>
  <collision>
    <origin xyz="0.0 0.05 -0.045" rpy="0 0 0"/>
    <geometry>
      <mesh filename="../meshes/Hip_v1_1.stl"/>
    </geometry>
  </collision>
</link>

<link name="Hip_v1__1__1">
  <inertial>
    <origin xyz="0.0022984441069888646 -8.467524527377979e-07 -0.013356564577291966" rpy="0 0 0"/>
    <mass value="0.07120981938348954"/>
    <inertia ixx="2.6e-05" iyy="7e-05" izz="5.4e-05" ixy="0.0" iyz="0.0" ixz="0.0"/>
  </inertial>
  <visual>
    <origin xyz="0.0 -0.05 -0.045" rpy="0 0 0"/>
    <geometry>
      <mesh filename="../meshes/Hip_v1__1__1.stl"/>
    </geometry>
    <material name="silver"/>
  </visual>
  <collision>
    <origin xyz="0.0 -0.05 -0.045" rpy="0 0 0"/>
    <geometry>
      <mesh filename="../meshes/Hip_v1__1__1.stl"/>
    </geometry>
  </collision>
</link>

<link name="Hip_joint_v1_1">
  <inertial>
    <origin xyz="-0.03822219731670722 -2.063442687480488e-07 -2.3112192325615494e-05" rpy="0 0 0"/>
    <mass value="0.015566398617684687"/>
    <inertia ixx="1e-06" iyy="5e-06" izz="6e-06" ixy="-0.0" iyz="-0.0" ixz="-0.0"/>
  </inertial>
  <visual>
    <origin xyz="-0.04 -0.05 0.000328" rpy="0 0 0"/>
    <geometry>
      <mesh filename="../meshes/Hip_joint_v1_1.stl"/>
    </geometry>
    <material name="silver"/>
  </visual>
  <collision>
    <origin xyz="-0.04 -0.05 0.000328" rpy="0 0 0"/>
    <geometry>
      <mesh filename="../meshes/Hip_joint_v1_1.stl"/>
    </geometry>
  </collision>
</link>

<joint name="left_hip_pitch" type="continuous">
  <origin xyz="-0.04 -0.02 -7.1e-05" rpy="0 0 0"/>
  <parent link="Hip_joint_v1_1"/>
  <child link="Upper_leg_v2__1__1"/>
  <axis xyz="-0.0 -1.0 -0.0"/>
</joint>

<joint name="left_knee" type="continuous">
  <origin xyz="0.0 0.005 -0.14" rpy="0 0 0"/>
  <parent link="Upper_leg_v2__1__1"/>
  <child link="Lower_leg_v2__1__1"/>
  <axis xyz="0.0 1.0 0.0"/>
</joint>

<joint name="right_knee" type="continuous">
  <origin xyz="0.0 0.005 -0.14" rpy="0 0 0"/>
  <parent link="Upper_leg_v2_1"/>
  <child link="Lower_leg_v2_1"/>
  <axis xyz="0.0 1.0 0.0"/>
</joint>

<joint name="right_ankle_pitch" type="continuous">
  <origin xyz="0.0 0.0 -0.14" rpy="0 0 0"/>
  <parent link="Lower_leg_v2_1"/>
  <child link="Ankle_v1__1__1"/>
  <axis xyz="-0.0 -1.0 -0.0"/>
</joint>

<joint name="left_ankle_pitch" type="continuous">
  <origin xyz="0.0 0.0 -0.14" rpy="0 0 0"/>
  <parent link="Lower_leg_v2__1__1"/>
  <child link="Ankle_v1__2__1"/>
  <axis xyz="-0.0 -1.0 -0.0"/>
</joint>

<joint name="left_ankle_roll" type="continuous">
  <origin xyz="-0.035 0.015 7.1e-05" rpy="0 0 0"/>
  <parent link="Ankle_v1__2__1"/>
  <child link="Foot_v1__1__1"/>
  <axis xyz="-1.0 -0.0 -0.0"/>
</joint>

<joint name="right_ankle_roll" type="continuous">
  <origin xyz="-0.035 0.015 7e-05" rpy="0 0 0"/>
  <parent link="Ankle_v1__1__1"/>
  <child link="Foot_v1_1"/>
  <axis xyz="-1.0 0.0 -0.0"/>
</joint>

<joint name="right_hip_roll" type="continuous">
  <origin xyz="0.04 0.0 -0.045328" rpy="0 0 0"/>
  <parent link="Hip_v1_1"/>
  <child link="Hip_joint_v1__1__1"/>
  <axis xyz="-1.0 0.0 -0.0"/>
</joint>

<joint name="right_hip_pitch" type="continuous">
  <origin xyz="-0.04 -0.02 7e-05" rpy="0 0 0"/>
  <parent link="Hip_joint_v1__1__1"/>
  <child link="Upper_leg_v2_1"/>
  <axis xyz="-0.0 -1.0 -0.0"/>
</joint>

<joint name="left_hip_yaw" type="continuous">
  <origin xyz="0.0 -0.05 0.045" rpy="0 0 0"/>
  <parent link="base_link"/>
  <child link="Hip_v1_1"/>
  <axis xyz="-0.0 0.0 1.0"/>
</joint>

<joint name="right_hip_yaw" type="continuous">
  <origin xyz="0.0 0.05 0.045" rpy="0 0 0"/>
  <parent link="base_link"/>
  <child link="Hip_v1__1__1"/>
  <axis xyz="-0.0 0.0 1.0"/>
</joint>

<joint name="left_hip_roll" type="continuous">
  <origin xyz="0.04 0.0 -0.045328" rpy="0 0 0"/>
  <parent link="Hip_v1__1__1"/>
  <child link="Hip_joint_v1_1"/>
  <axis xyz="-1.0 0.0 -0.0"/>
</joint>

</robot>
